{
 "cells": [
  {
   "cell_type": "markdown",
   "metadata": {},
   "source": [
    "# Introduction\n",
    "This AI will create a model to determine a NSFW content, which is producted by a Stable Diffusion Model. Untill now there are only bad NSFW detectors. We will try to make one model specific, by creating safe and not safe content from the SD Model, classifying it manualy and creating this ML model to classify the content. It should be applicable to any model."
   ]
  },
  {
   "cell_type": "markdown",
   "metadata": {},
   "source": [
    "## Start the SD Server"
   ]
  },
  {
   "cell_type": "code",
   "execution_count": null,
   "metadata": {},
   "outputs": [
    {
     "name": "stderr",
     "output_type": "stream",
     "text": [
      "ERROR:root:Internal Python error in the inspect module.\n",
      "Below is the traceback from this internal error.\n",
      "\n",
      "ERROR:root:Internal Python error in the inspect module.\n",
      "Below is the traceback from this internal error.\n",
      "\n",
      "ERROR:root:Internal Python error in the inspect module.\n",
      "Below is the traceback from this internal error.\n",
      "\n"
     ]
    },
    {
     "name": "stdout",
     "output_type": "stream",
     "text": [
      "Traceback (most recent call last):\n",
      "  File \"c:\\users\\rybak\\appdata\\local\\programs\\python\\python37\\lib\\site-packages\\IPython\\core\\interactiveshell.py\", line 3417, in run_code\n",
      "    exec(code_obj, self.user_global_ns, self.user_ns)\n",
      "  File \"<ipython-input-8-b052b54b73bc>\", line 9, in <module>\n",
      "    model = predict.load_model('./help_nsfw_detector/model/saved_model.h5')\n",
      "  File \"C:\\Users\\Rybak\\Desktop\\react\\PicGenApp\\backEnd\\nsfw_detector\\customDetector\\help_nsfw_detector\\predict.py\", line 55, in load_model\n",
      "    model = tf.keras.models.load_model(model_path, custom_objects={'KerasLayer': hub.KerasLayer},compile=False)\n",
      "AttributeError: module 'tensorflow' has no attribute 'keras'\n",
      "\n",
      "During handling of the above exception, another exception occurred:\n",
      "\n",
      "Traceback (most recent call last):\n",
      "  File \"c:\\users\\rybak\\appdata\\local\\programs\\python\\python37\\lib\\site-packages\\IPython\\core\\interactiveshell.py\", line 2044, in showtraceback\n",
      "    stb = value._render_traceback_()\n",
      "AttributeError: 'AttributeError' object has no attribute '_render_traceback_'\n",
      "\n",
      "During handling of the above exception, another exception occurred:\n",
      "\n",
      "Traceback (most recent call last):\n",
      "  File \"c:\\users\\rybak\\appdata\\local\\programs\\python\\python37\\lib\\site-packages\\IPython\\core\\ultratb.py\", line 1169, in get_records\n",
      "    return _fixed_getinnerframes(etb, number_of_lines_of_context, tb_offset)\n",
      "  File \"c:\\users\\rybak\\appdata\\local\\programs\\python\\python37\\lib\\site-packages\\IPython\\core\\ultratb.py\", line 316, in wrapped\n",
      "    return f(*args, **kwargs)\n",
      "  File \"c:\\users\\rybak\\appdata\\local\\programs\\python\\python37\\lib\\site-packages\\IPython\\core\\ultratb.py\", line 350, in _fixed_getinnerframes\n",
      "    records = fix_frame_records_filenames(inspect.getinnerframes(etb, context))\n",
      "  File \"c:\\users\\rybak\\appdata\\local\\programs\\python\\python37\\lib\\inspect.py\", line 1495, in getinnerframes\n",
      "    frameinfo = (tb.tb_frame,) + getframeinfo(tb, context)\n",
      "  File \"c:\\users\\rybak\\appdata\\local\\programs\\python\\python37\\lib\\inspect.py\", line 1453, in getframeinfo\n",
      "    filename = getsourcefile(frame) or getfile(frame)\n",
      "  File \"c:\\users\\rybak\\appdata\\local\\programs\\python\\python37\\lib\\inspect.py\", line 696, in getsourcefile\n",
      "    if getattr(getmodule(object, filename), '__loader__', None) is not None:\n",
      "  File \"c:\\users\\rybak\\appdata\\local\\programs\\python\\python37\\lib\\inspect.py\", line 733, in getmodule\n",
      "    if ismodule(module) and hasattr(module, '__file__'):\n",
      "  File \"C:\\Users\\Rybak\\AppData\\Roaming\\Python\\Python37\\site-packages\\tensorflow\\__init__.py\", line 50, in __getattr__\n",
      "    module = self._load()\n",
      "  File \"C:\\Users\\Rybak\\AppData\\Roaming\\Python\\Python37\\site-packages\\tensorflow\\__init__.py\", line 44, in _load\n",
      "    module = _importlib.import_module(self.__name__)\n",
      "  File \"c:\\users\\rybak\\appdata\\local\\programs\\python\\python37\\lib\\importlib\\__init__.py\", line 127, in import_module\n",
      "    return _bootstrap._gcd_import(name[level:], package, level)\n",
      "  File \"<frozen importlib._bootstrap>\", line 1006, in _gcd_import\n",
      "  File \"<frozen importlib._bootstrap>\", line 983, in _find_and_load\n",
      "  File \"<frozen importlib._bootstrap>\", line 953, in _find_and_load_unlocked\n",
      "  File \"<frozen importlib._bootstrap>\", line 219, in _call_with_frames_removed\n",
      "  File \"<frozen importlib._bootstrap>\", line 1006, in _gcd_import\n",
      "  File \"<frozen importlib._bootstrap>\", line 983, in _find_and_load\n",
      "ERROR! Session/line number was not unique in  File \"<frozen importlib._bootstrap>\", line 967, in _find_and_load_unlocked\n",
      "  File \"<frozen importlib._bootstrap>\", line 677, in _load_unlocked\n",
      "  File \"<frozen importlib._bootstrap_external>\", line 728, in exec_module\n",
      " database. History logging moved to new session 265\n",
      "  File \"<frozen importlib._bootstrap>\", line 219, in _call_with_frames_removed\n",
      "  File \"C:\\Users\\Rybak\\AppData\\Roaming\\Python\\Python37\\site-packages\\tensorflow_core\\__init__.py\", line 42, in <module>\n",
      "    from . _api.v2 import audio\n",
      "  File \"C:\\Users\\Rybak\\AppData\\Roaming\\Python\\Python37\\site-packages\\tensorflow_core\\_api\\v2\\audio\\__init__.py\", line 10, in <module>\n",
      "    from tensorflow.python.ops.gen_audio_ops import decode_wav\n",
      "  File \"C:\\Users\\Rybak\\AppData\\Roaming\\Python\\Python37\\site-packages\\tensorflow_core\\python\\ops\\gen_audio_ops.py\", line 10, in <module>\n",
      "    from tensorflow.python.eager import context as _context\n",
      "  File \"C:\\Users\\Rybak\\AppData\\Roaming\\Python\\Python37\\site-packages\\tensorflow_core\\python\\eager\\context.py\", line 29, in <module>\n",
      "    from tensorflow.core.protobuf import config_pb2\n",
      "  File \"C:\\Users\\Rybak\\AppData\\Roaming\\Python\\Python37\\site-packages\\tensorflow_core\\core\\protobuf\\config_pb2.py\", line 7, in <module>\n",
      "    from google.protobuf import descriptor as _descriptor\n",
      "ModuleNotFoundError: No module named 'google.protobuf'\n",
      "Traceback (most recent call last):\n",
      "  File \"c:\\users\\rybak\\appdata\\local\\programs\\python\\python37\\lib\\site-packages\\IPython\\core\\interactiveshell.py\", line 3417, in run_code\n",
      "    exec(code_obj, self.user_global_ns, self.user_ns)\n",
      "  File \"<ipython-input-8-b052b54b73bc>\", line 9, in <module>\n",
      "    model = predict.load_model('./help_nsfw_detector/model/saved_model.h5')\n",
      "  File \"C:\\Users\\Rybak\\Desktop\\react\\PicGenApp\\backEnd\\nsfw_detector\\customDetector\\help_nsfw_detector\\predict.py\", line 55, in load_model\n",
      "    model = tf.keras.models.load_model(model_path, custom_objects={'KerasLayer': hub.KerasLayer},compile=False)\n",
      "AttributeError: module 'tensorflow' has no attribute 'keras'\n",
      "\n",
      "During handling of the above exception, another exception occurred:\n",
      "\n",
      "Traceback (most recent call last):\n",
      "  File \"c:\\users\\rybak\\appdata\\local\\programs\\python\\python37\\lib\\site-packages\\IPython\\core\\interactiveshell.py\", line 2044, in showtraceback\n",
      "    stb = value._render_traceback_()\n",
      "AttributeError: 'AttributeError' object has no attribute '_render_traceback_'\n",
      "\n",
      "During handling of the above exception, another exception occurred:\n",
      "\n",
      "Traceback (most recent call last):\n",
      "  File \"c:\\users\\rybak\\appdata\\local\\programs\\python\\python37\\lib\\site-packages\\IPython\\core\\interactiveshell.py\", line 3337, in run_ast_nodes\n",
      "    if (await self.run_code(code, result,  async_=asy)):\n",
      "  File \"c:\\users\\rybak\\appdata\\local\\programs\\python\\python37\\lib\\site-packages\\IPython\\core\\interactiveshell.py\", line 3434, in run_code\n",
      "    self.showtraceback(running_compiled_code=True)\n",
      "  File \"c:\\users\\rybak\\appdata\\local\\programs\\python\\python37\\lib\\site-packages\\IPython\\core\\interactiveshell.py\", line 2047, in showtraceback\n",
      "    value, tb, tb_offset=tb_offset)\n",
      "  File \"c:\\users\\rybak\\appdata\\local\\programs\\python\\python37\\lib\\site-packages\\IPython\\core\\ultratb.py\", line 1436, in structured_traceback\n",
      "    self, etype, value, tb, tb_offset, number_of_lines_of_context)\n",
      "  File \"c:\\users\\rybak\\appdata\\local\\programs\\python\\python37\\lib\\site-packages\\IPython\\core\\ultratb.py\", line 1336, in structured_traceback\n",
      "    self, etype, value, tb, tb_offset, number_of_lines_of_context\n",
      "  File \"c:\\users\\rybak\\appdata\\local\\programs\\python\\python37\\lib\\site-packages\\IPython\\core\\ultratb.py\", line 1193, in structured_traceback\n",
      "    tb_offset)\n",
      "  File \"c:\\users\\rybak\\appdata\\local\\programs\\python\\python37\\lib\\site-packages\\IPython\\core\\ultratb.py\", line 1150, in format_exception_as_a_whole\n",
      "    last_unique, recursion_repeat = find_recursion(orig_etype, evalue, records)\n",
      "  File \"c:\\users\\rybak\\appdata\\local\\programs\\python\\python37\\lib\\site-packages\\IPython\\core\\ultratb.py\", line 451, in find_recursion\n",
      "    return len(records), 0\n",
      "TypeError: object of type 'NoneType' has no len()\n",
      "\n",
      "During handling of the above exception, another exception occurred:\n",
      "\n",
      "Traceback (most recent call last):\n",
      "  File \"c:\\users\\rybak\\appdata\\local\\programs\\python\\python37\\lib\\site-packages\\IPython\\core\\interactiveshell.py\", line 2044, in showtraceback\n",
      "    stb = value._render_traceback_()\n",
      "AttributeError: 'TypeError' object has no attribute '_render_traceback_'\n",
      "\n",
      "During handling of the above exception, another exception occurred:\n",
      "\n",
      "Traceback (most recent call last):\n",
      "  File \"c:\\users\\rybak\\appdata\\local\\programs\\python\\python37\\lib\\site-packages\\IPython\\core\\ultratb.py\", line 1169, in get_records\n",
      "    return _fixed_getinnerframes(etb, number_of_lines_of_context, tb_offset)\n",
      "  File \"c:\\users\\rybak\\appdata\\local\\programs\\python\\python37\\lib\\site-packages\\IPython\\core\\ultratb.py\", line 316, in wrapped\n",
      "    return f(*args, **kwargs)\n",
      "  File \"c:\\users\\rybak\\appdata\\local\\programs\\python\\python37\\lib\\site-packages\\IPython\\core\\ultratb.py\", line 350, in _fixed_getinnerframes\n",
      "    records = fix_frame_records_filenames(inspect.getinnerframes(etb, context))\n",
      "  File \"c:\\users\\rybak\\appdata\\local\\programs\\python\\python37\\lib\\inspect.py\", line 1495, in getinnerframes\n",
      "    frameinfo = (tb.tb_frame,) + getframeinfo(tb, context)\n",
      "  File \"c:\\users\\rybak\\appdata\\local\\programs\\python\\python37\\lib\\inspect.py\", line 1453, in getframeinfo\n",
      "    filename = getsourcefile(frame) or getfile(frame)\n",
      "  File \"c:\\users\\rybak\\appdata\\local\\programs\\python\\python37\\lib\\inspect.py\", line 696, in getsourcefile\n",
      "    if getattr(getmodule(object, filename), '__loader__', None) is not None:\n",
      "  File \"c:\\users\\rybak\\appdata\\local\\programs\\python\\python37\\lib\\inspect.py\", line 733, in getmodule\n",
      "    if ismodule(module) and hasattr(module, '__file__'):\n",
      "  File \"C:\\Users\\Rybak\\AppData\\Roaming\\Python\\Python37\\site-packages\\tensorflow\\__init__.py\", line 50, in __getattr__\n",
      "    module = self._load()\n",
      "  File \"C:\\Users\\Rybak\\AppData\\Roaming\\Python\\Python37\\site-packages\\tensorflow\\__init__.py\", line 44, in _load\n",
      "    module = _importlib.import_module(self.__name__)\n",
      "  File \"c:\\users\\rybak\\appdata\\local\\programs\\python\\python37\\lib\\importlib\\__init__.py\", line 127, in import_module\n",
      "    return _bootstrap._gcd_import(name[level:], package, level)\n",
      "  File \"<frozen importlib._bootstrap>\", line 1006, in _gcd_import\n",
      "  File \"<frozen importlib._bootstrap>\", line 983, in _find_and_load\n",
      "  File \"<frozen importlib._bootstrap>\", line 953, in _find_and_load_unlocked\n",
      "  File \"<frozen importlib._bootstrap>\", line 219, in _call_with_frames_removed\n",
      "  File \"<frozen importlib._bootstrap>\", line 1006, in _gcd_import\n",
      "  File \"<frozen importlib._bootstrap>\", line 983, in _find_and_load\n",
      "  File \"<frozen importlib._bootstrap>\", line 967, in _find_and_load_unlocked\n",
      "  File \"<frozen importlib._bootstrap>\", line 677, in _load_unlocked\n",
      "  File \"<frozen importlib._bootstrap_external>\", line 728, in exec_module\n",
      "  File \"<frozen importlib._bootstrap>\", line 219, in _call_with_frames_removed\n",
      "  File \"C:\\Users\\Rybak\\AppData\\Roaming\\Python\\Python37\\site-packages\\tensorflow_core\\__init__.py\", line 42, in <module>\n",
      "    from . _api.v2 import audio\n",
      "  File \"C:\\Users\\Rybak\\AppData\\Roaming\\Python\\Python37\\site-packages\\tensorflow_core\\_api\\v2\\audio\\__init__.py\", line 10, in <module>\n",
      "    from tensorflow.python.ops.gen_audio_ops import decode_wav\n",
      "  File \"C:\\Users\\Rybak\\AppData\\Roaming\\Python\\Python37\\site-packages\\tensorflow_core\\python\\ops\\gen_audio_ops.py\", line 10, in <module>\n",
      "    from tensorflow.python.eager import context as _context\n",
      "  File \"C:\\Users\\Rybak\\AppData\\Roaming\\Python\\Python37\\site-packages\\tensorflow_core\\python\\eager\\context.py\", line 29, in <module>\n",
      "    from tensorflow.core.protobuf import config_pb2\n",
      "  File \"C:\\Users\\Rybak\\AppData\\Roaming\\Python\\Python37\\site-packages\\tensorflow_core\\core\\protobuf\\config_pb2.py\", line 7, in <module>\n",
      "    from google.protobuf import descriptor as _descriptor\n",
      "ModuleNotFoundError: No module named 'google.protobuf'\n",
      "Traceback (most recent call last):\n",
      "  File \"c:\\users\\rybak\\appdata\\local\\programs\\python\\python37\\lib\\site-packages\\IPython\\core\\interactiveshell.py\", line 3417, in run_code\n",
      "    exec(code_obj, self.user_global_ns, self.user_ns)\n",
      "  File \"<ipython-input-8-b052b54b73bc>\", line 9, in <module>\n",
      "    model = predict.load_model('./help_nsfw_detector/model/saved_model.h5')\n",
      "  File \"C:\\Users\\Rybak\\Desktop\\react\\PicGenApp\\backEnd\\nsfw_detector\\customDetector\\help_nsfw_detector\\predict.py\", line 55, in load_model\n",
      "    model = tf.keras.models.load_model(model_path, custom_objects={'KerasLayer': hub.KerasLayer},compile=False)\n",
      "AttributeError: module 'tensorflow' has no attribute 'keras'\n",
      "\n",
      "During handling of the above exception, another exception occurred:\n",
      "\n",
      "Traceback (most recent call last):\n",
      "  File \"c:\\users\\rybak\\appdata\\local\\programs\\python\\python37\\lib\\site-packages\\IPython\\core\\interactiveshell.py\", line 2044, in showtraceback\n",
      "    stb = value._render_traceback_()\n",
      "AttributeError: 'AttributeError' object has no attribute '_render_traceback_'\n",
      "\n",
      "During handling of the above exception, another exception occurred:\n",
      "\n",
      "Traceback (most recent call last):\n",
      "  File \"c:\\users\\rybak\\appdata\\local\\programs\\python\\python37\\lib\\site-packages\\IPython\\core\\interactiveshell.py\", line 3337, in run_ast_nodes\n",
      "    if (await self.run_code(code, result,  async_=asy)):\n",
      "  File \"c:\\users\\rybak\\appdata\\local\\programs\\python\\python37\\lib\\site-packages\\IPython\\core\\interactiveshell.py\", line 3434, in run_code\n",
      "    self.showtraceback(running_compiled_code=True)\n",
      "  File \"c:\\users\\rybak\\appdata\\local\\programs\\python\\python37\\lib\\site-packages\\IPython\\core\\interactiveshell.py\", line 2047, in showtraceback\n",
      "    value, tb, tb_offset=tb_offset)\n",
      "  File \"c:\\users\\rybak\\appdata\\local\\programs\\python\\python37\\lib\\site-packages\\IPython\\core\\ultratb.py\", line 1436, in structured_traceback\n",
      "    self, etype, value, tb, tb_offset, number_of_lines_of_context)\n",
      "  File \"c:\\users\\rybak\\appdata\\local\\programs\\python\\python37\\lib\\site-packages\\IPython\\core\\ultratb.py\", line 1336, in structured_traceback\n",
      "    self, etype, value, tb, tb_offset, number_of_lines_of_context\n",
      "  File \"c:\\users\\rybak\\appdata\\local\\programs\\python\\python37\\lib\\site-packages\\IPython\\core\\ultratb.py\", line 1193, in structured_traceback\n",
      "    tb_offset)\n",
      "  File \"c:\\users\\rybak\\appdata\\local\\programs\\python\\python37\\lib\\site-packages\\IPython\\core\\ultratb.py\", line 1150, in format_exception_as_a_whole\n",
      "    last_unique, recursion_repeat = find_recursion(orig_etype, evalue, records)\n",
      "  File \"c:\\users\\rybak\\appdata\\local\\programs\\python\\python37\\lib\\site-packages\\IPython\\core\\ultratb.py\", line 451, in find_recursion\n",
      "    return len(records), 0\n",
      "TypeError: object of type 'NoneType' has no len()\n",
      "\n",
      "During handling of the above exception, another exception occurred:\n",
      "\n",
      "Traceback (most recent call last):\n",
      "  File \"c:\\users\\rybak\\appdata\\local\\programs\\python\\python37\\lib\\site-packages\\IPython\\core\\interactiveshell.py\", line 2044, in showtraceback\n",
      "    stb = value._render_traceback_()\n",
      "AttributeError: 'TypeError' object has no attribute '_render_traceback_'\n",
      "\n",
      "During handling of the above exception, another exception occurred:\n",
      "\n",
      "Traceback (most recent call last):\n",
      "  File \"c:\\users\\rybak\\appdata\\local\\programs\\python\\python37\\lib\\site-packages\\IPython\\core\\interactiveshell.py\", line 2922, in _run_cell\n",
      "    return runner(coro)\n",
      "  File \"c:\\users\\rybak\\appdata\\local\\programs\\python\\python37\\lib\\site-packages\\IPython\\core\\async_helpers.py\", line 68, in _pseudo_sync_runner\n",
      "    coro.send(None)\n",
      "  File \"c:\\users\\rybak\\appdata\\local\\programs\\python\\python37\\lib\\site-packages\\IPython\\core\\interactiveshell.py\", line 3146, in run_cell_async\n",
      "    interactivity=interactivity, compiler=compiler, result=result)\n",
      "  File \"c:\\users\\rybak\\appdata\\local\\programs\\python\\python37\\lib\\site-packages\\IPython\\core\\interactiveshell.py\", line 3356, in run_ast_nodes\n",
      "    self.showtraceback()\n",
      "  File \"c:\\users\\rybak\\appdata\\local\\programs\\python\\python37\\lib\\site-packages\\IPython\\core\\interactiveshell.py\", line 2047, in showtraceback\n",
      "    value, tb, tb_offset=tb_offset)\n",
      "  File \"c:\\users\\rybak\\appdata\\local\\programs\\python\\python37\\lib\\site-packages\\IPython\\core\\ultratb.py\", line 1436, in structured_traceback\n",
      "    self, etype, value, tb, tb_offset, number_of_lines_of_context)\n",
      "  File \"c:\\users\\rybak\\appdata\\local\\programs\\python\\python37\\lib\\site-packages\\IPython\\core\\ultratb.py\", line 1336, in structured_traceback\n",
      "    self, etype, value, tb, tb_offset, number_of_lines_of_context\n",
      "  File \"c:\\users\\rybak\\appdata\\local\\programs\\python\\python37\\lib\\site-packages\\IPython\\core\\ultratb.py\", line 1211, in structured_traceback\n",
      "    chained_exceptions_tb_offset)\n",
      "  File \"c:\\users\\rybak\\appdata\\local\\programs\\python\\python37\\lib\\site-packages\\IPython\\core\\ultratb.py\", line 1150, in format_exception_as_a_whole\n",
      "    last_unique, recursion_repeat = find_recursion(orig_etype, evalue, records)\n",
      "  File \"c:\\users\\rybak\\appdata\\local\\programs\\python\\python37\\lib\\site-packages\\IPython\\core\\ultratb.py\", line 451, in find_recursion\n",
      "    return len(records), 0\n",
      "TypeError: object of type 'NoneType' has no len()\n",
      "\n",
      "During handling of the above exception, another exception occurred:\n",
      "\n",
      "Traceback (most recent call last):\n",
      "  File \"c:\\users\\rybak\\appdata\\local\\programs\\python\\python37\\lib\\site-packages\\IPython\\core\\interactiveshell.py\", line 2044, in showtraceback\n",
      "    stb = value._render_traceback_()\n",
      "AttributeError: 'TypeError' object has no attribute '_render_traceback_'\n",
      "\n",
      "During handling of the above exception, another exception occurred:\n",
      "\n",
      "Traceback (most recent call last):\n",
      "  File \"c:\\users\\rybak\\appdata\\local\\programs\\python\\python37\\lib\\site-packages\\IPython\\core\\ultratb.py\", line 1169, in get_records\n",
      "    return _fixed_getinnerframes(etb, number_of_lines_of_context, tb_offset)\n",
      "  File \"c:\\users\\rybak\\appdata\\local\\programs\\python\\python37\\lib\\site-packages\\IPython\\core\\ultratb.py\", line 316, in wrapped\n",
      "    return f(*args, **kwargs)\n",
      "  File \"c:\\users\\rybak\\appdata\\local\\programs\\python\\python37\\lib\\site-packages\\IPython\\core\\ultratb.py\", line 350, in _fixed_getinnerframes\n",
      "    records = fix_frame_records_filenames(inspect.getinnerframes(etb, context))\n",
      "  File \"c:\\users\\rybak\\appdata\\local\\programs\\python\\python37\\lib\\inspect.py\", line 1495, in getinnerframes\n",
      "    frameinfo = (tb.tb_frame,) + getframeinfo(tb, context)\n",
      "  File \"c:\\users\\rybak\\appdata\\local\\programs\\python\\python37\\lib\\inspect.py\", line 1453, in getframeinfo\n",
      "    filename = getsourcefile(frame) or getfile(frame)\n",
      "  File \"c:\\users\\rybak\\appdata\\local\\programs\\python\\python37\\lib\\inspect.py\", line 696, in getsourcefile\n",
      "    if getattr(getmodule(object, filename), '__loader__', None) is not None:\n",
      "  File \"c:\\users\\rybak\\appdata\\local\\programs\\python\\python37\\lib\\inspect.py\", line 733, in getmodule\n",
      "    if ismodule(module) and hasattr(module, '__file__'):\n",
      "  File \"C:\\Users\\Rybak\\AppData\\Roaming\\Python\\Python37\\site-packages\\tensorflow\\__init__.py\", line 50, in __getattr__\n",
      "    module = self._load()\n",
      "  File \"C:\\Users\\Rybak\\AppData\\Roaming\\Python\\Python37\\site-packages\\tensorflow\\__init__.py\", line 44, in _load\n",
      "    module = _importlib.import_module(self.__name__)\n",
      "  File \"c:\\users\\rybak\\appdata\\local\\programs\\python\\python37\\lib\\importlib\\__init__.py\", line 127, in import_module\n",
      "    return _bootstrap._gcd_import(name[level:], package, level)\n",
      "  File \"<frozen importlib._bootstrap>\", line 1006, in _gcd_import\n",
      "  File \"<frozen importlib._bootstrap>\", line 983, in _find_and_load\n",
      "  File \"<frozen importlib._bootstrap>\", line 953, in _find_and_load_unlocked\n",
      "  File \"<frozen importlib._bootstrap>\", line 219, in _call_with_frames_removed\n",
      "  File \"<frozen importlib._bootstrap>\", line 1006, in _gcd_import\n",
      "  File \"<frozen importlib._bootstrap>\", line 983, in _find_and_load\n",
      "  File \"<frozen importlib._bootstrap>\", line 967, in _find_and_load_unlocked\n",
      "  File \"<frozen importlib._bootstrap>\", line 677, in _load_unlocked\n",
      "  File \"<frozen importlib._bootstrap_external>\", line 728, in exec_module\n",
      "  File \"<frozen importlib._bootstrap>\", line 219, in _call_with_frames_removed\n",
      "  File \"C:\\Users\\Rybak\\AppData\\Roaming\\Python\\Python37\\site-packages\\tensorflow_core\\__init__.py\", line 42, in <module>\n",
      "    from . _api.v2 import audio\n",
      "  File \"C:\\Users\\Rybak\\AppData\\Roaming\\Python\\Python37\\site-packages\\tensorflow_core\\_api\\v2\\audio\\__init__.py\", line 10, in <module>\n",
      "    from tensorflow.python.ops.gen_audio_ops import decode_wav\n",
      "  File \"C:\\Users\\Rybak\\AppData\\Roaming\\Python\\Python37\\site-packages\\tensorflow_core\\python\\ops\\gen_audio_ops.py\", line 10, in <module>\n",
      "    from tensorflow.python.eager import context as _context\n",
      "  File \"C:\\Users\\Rybak\\AppData\\Roaming\\Python\\Python37\\site-packages\\tensorflow_core\\python\\eager\\context.py\", line 29, in <module>\n",
      "    from tensorflow.core.protobuf import config_pb2\n",
      "  File \"C:\\Users\\Rybak\\AppData\\Roaming\\Python\\Python37\\site-packages\\tensorflow_core\\core\\protobuf\\config_pb2.py\", line 7, in <module>\n",
      "    from google.protobuf import descriptor as _descriptor\n",
      "ModuleNotFoundError: No module named 'google.protobuf'\n"
     ]
    }
   ],
   "source": [
    "import pandas as pd\n",
    "import json\n",
    "import base64\n",
    "import time\n",
    "import requests\n",
    "\n",
    "# helper to precassify the images\n",
    "from help_nsfw_detector import predict\n",
    "model = predict.load_model('./help_nsfw_detector/model/saved_model.h5')\n",
    "\n",
    "# move files\n",
    "import os\n",
    "import shutil"
   ]
  },
  {
   "cell_type": "markdown",
   "metadata": {},
   "source": [
    "## Load Prompts"
   ]
  },
  {
   "cell_type": "code",
   "execution_count": 5,
   "metadata": {},
   "outputs": [
    {
     "data": {
      "text/plain": [
       "73718"
      ]
     },
     "execution_count": 5,
     "metadata": {},
     "output_type": "execute_result"
    }
   ],
   "source": [
    "SafePosPrompt = pd.read_csv('safe pos prompts.csv', delimiter=\";\")\n",
    "NotSafePosPrompt = pd.read_csv('not safe pos prompts.csv', delimiter=\";\")\n",
    "NegPrompt = pd.read_csv('neg prompt.csv', delimiter=\";\")\n",
    "\n",
    "#for row in range(len(SafePosPrompt)):\n",
    "#    print(SafePosPrompt.at[row, 'prompt'])\n",
    "len(SafePosPrompt)"
   ]
  },
  {
   "cell_type": "markdown",
   "metadata": {},
   "source": [
    "## Setup the Server"
   ]
  },
  {
   "cell_type": "code",
   "execution_count": 6,
   "metadata": {},
   "outputs": [
    {
     "name": "stdout",
     "output_type": "stream",
     "text": [
      "<Response [200]>\n"
     ]
    }
   ],
   "source": [
    "url = \"http://192.168.0.109:7861\"\n",
    "# this will change the model on the backend server\n",
    "option_payload = {\n",
    "    #\"sd_model_checkpoint\": \"AnythingV5_v32.safetensors\", # switch model\n",
    "    \"sd_model_checkpoint\": \"animeModel_UpdateV10ImUsing.safetensors\", # switch model\n",
    "}\n",
    "\n",
    "response = requests.post(url=f'{url}/sdapi/v1/options', json=option_payload)\n",
    "\n",
    "print(response)"
   ]
  },
  {
   "cell_type": "markdown",
   "metadata": {},
   "source": [
    "## Generate Pictures"
   ]
  },
  {
   "cell_type": "markdown",
   "metadata": {},
   "source": [
    "### Helper Defs"
   ]
  },
  {
   "cell_type": "code",
   "execution_count": 7,
   "metadata": {},
   "outputs": [],
   "source": [
    "def submit_post(url: str, data: dict):\n",
    "    \"\"\"\n",
    "    Submit a POST request to the given URL with the given data.\n",
    "    \"\"\"\n",
    "    return requests.post(url, data=json.dumps(data))\n",
    "def save_encoded_image(b64_image: str, output_path: str):\n",
    "    filename = time.strftime(\"%Y%m%d-%H%M%S\") + \"_picture.png\"\n",
    "    full_path = output_path + filename\n",
    "    \"\"\"\n",
    "    Save the given image to the given output path.\n",
    "    \"\"\"\n",
    "    with open(full_path, \"wb\") as image_file:\n",
    "        image_file.write(base64.b64decode(b64_image))\n",
    "    return full_path\n",
    "def nsfw_detector(image_path:str):\n",
    "    predict_df = predict.classify(model, [image_path])\n",
    "    hentai = predict_df[image_path][\"hentai\"]\n",
    "    porn = predict_df[image_path][\"porn\"]\n",
    "    if porn > 0.01 or hentai > 0.01:\n",
    "        return True # explicit content\n",
    "    else:\n",
    "        return False # not explicit content"
   ]
  },
  {
   "cell_type": "code",
   "execution_count": null,
   "metadata": {},
   "outputs": [
    {
     "name": "stdout",
     "output_type": "stream",
     "text": [
      "100 images will be generated - NSFW\n"
     ]
    },
    {
     "name": "stderr",
     "output_type": "stream",
     "text": [
      "ERROR:root:Internal Python error in the inspect module.\n",
      "Below is the traceback from this internal error.\n",
      "\n",
      "ERROR:root:Internal Python error in the inspect module.\n",
      "Below is the traceback from this internal error.\n",
      "\n",
      "ERROR:root:Internal Python error in the inspect module.\n",
      "Below is the traceback from this internal error.\n",
      "\n"
     ]
    },
    {
     "name": "stdout",
     "output_type": "stream",
     "text": [
      "Traceback (most recent call last):\n",
      "  File \"c:\\users\\rybak\\appdata\\local\\programs\\python\\python37\\lib\\site-packages\\IPython\\core\\interactiveshell.py\", line 3417, in run_code\n",
      "    exec(code_obj, self.user_global_ns, self.user_ns)\n",
      "  File \"<ipython-input-8-05c9b8348bf4>\", line 11, in <module>\n",
      "    isNSFW = nsfw_detector(\"./\" + full_path)\n",
      "NameError: name 'full_path' is not defined\n",
      "\n",
      "During handling of the above exception, another exception occurred:\n",
      "\n",
      "Traceback (most recent call last):\n",
      "  File \"c:\\users\\rybak\\appdata\\local\\programs\\python\\python37\\lib\\site-packages\\IPython\\core\\interactiveshell.py\", line 2044, in showtraceback\n",
      "    stb = value._render_traceback_()\n",
      "AttributeError: 'NameError' object has no attribute '_render_traceback_'\n",
      "\n",
      "During handling of the above exception, another exception occurred:\n",
      "\n",
      "Traceback (most recent call last):\n",
      "  File \"c:\\users\\rybak\\appdata\\local\\programs\\python\\python37\\lib\\site-packages\\IPython\\core\\ultratb.py\", line 1169, in get_records\n",
      "    return _fixed_getinnerframes(etb, number_of_lines_of_context, tb_offset)\n",
      "  File \"c:\\users\\rybak\\appdata\\local\\programs\\python\\python37\\lib\\site-packages\\IPython\\core\\ultratb.py\", line 316, in wrapped\n",
      "    return f(*args, **kwargs)\n",
      "  File \"c:\\users\\rybak\\appdata\\local\\programs\\python\\python37\\lib\\site-packages\\IPython\\core\\ultratb.py\", line 350, in _fixed_getinnerframes\n",
      "    records = fix_frame_records_filenames(inspect.getinnerframes(etb, context))\n",
      "  File \"c:\\users\\rybak\\appdata\\local\\programs\\python\\python37\\lib\\inspect.py\", line 1495, in getinnerframes\n",
      "    frameinfo = (tb.tb_frame,) + getframeinfo(tb, context)\n",
      "  File \"c:\\users\\rybak\\appdata\\local\\programs\\python\\python37\\lib\\inspect.py\", line 1453, in getframeinfo\n",
      "    filename = getsourcefile(frame) or getfile(frame)\n",
      "  File \"c:\\users\\rybak\\appdata\\local\\programs\\python\\python37\\lib\\inspect.py\", line 696, in getsourcefile\n",
      "    if getattr(getmodule(object, filename), '__loader__', None) is not None:\n",
      "  File \"c:\\users\\rybak\\appdata\\local\\programs\\python\\python37\\lib\\inspect.py\", line 733, in getmodule\n",
      "    if ismodule(module) and hasattr(module, '__file__'):\n",
      "  File \"C:\\Users\\Rybak\\AppData\\Roaming\\Python\\Python37\\site-packages\\tensorflow\\__init__.py\", line 50, in __getattr__\n",
      "    module = self._load()\n",
      "  File \"C:\\Users\\Rybak\\AppData\\Roaming\\Python\\Python37\\site-packages\\tensorflow\\__init__.py\", line 44, in _load\n",
      "    module = _importlib.import_module(self.__name__)\n",
      "  File \"c:\\users\\rybak\\appdata\\local\\programs\\python\\python37\\lib\\importlib\\__init__.py\", line 127, in import_module\n",
      "    return _bootstrap._gcd_import(name[level:], package, level)\n",
      "  File \"<frozen importlib._bootstrap>\", line 1006, in _gcd_import\n",
      "  File \"<frozen importlib._bootstrap>\", line 983, in _find_and_load\n",
      "  File \"<frozen importlib._bootstrap>\", line 953, in _find_and_load_unlocked\n",
      "  File \"<frozen importlib._bootstrap>\", line 219, in _call_with_frames_removed\n",
      "  File \"<frozen importlib._bootstrap>\", line 1006, in _gcd_import\n",
      "  File \"<frozen importlib._bootstrap>\", line 983, in _find_and_load\n",
      "  File \"<frozen importlib._bootstrap>\", line 967, in _find_and_load_unlocked\n",
      "  File \"<frozen importlib._bootstrap>\", line 677, in _load_unlocked\n",
      "  File \"<frozen importlib._bootstrap_external>\", line 728, in exec_module\n",
      "  File \"<frozen importlib._bootstrap>\", line 219, in _call_with_frames_removed\n",
      "  File \"C:\\Users\\Rybak\\AppData\\Roaming\\Python\\Python37\\site-packages\\tensorflow_core\\__init__.py\", line 42, in <module>\n",
      "    from . _api.v2 import audio\n",
      "  File \"C:\\Users\\Rybak\\AppData\\Roaming\\Python\\Python37\\site-packages\\tensorflow_core\\_api\\v2\\audio\\__init__.py\", line 10, in <module>\n",
      "    from tensorflow.python.ops.gen_audio_ops import decode_wav\n",
      "  File \"C:\\Users\\Rybak\\AppData\\Roaming\\Python\\Python37\\site-packages\\tensorflow_core\\python\\ops\\gen_audio_ops.py\", line 10, in <module>\n",
      "    from tensorflow.python.eager import context as _context\n",
      "  File \"C:\\Users\\Rybak\\AppData\\Roaming\\Python\\Python37\\site-packages\\tensorflow_core\\python\\eager\\context.py\", line 29, in <module>\n",
      "    from tensorflow.core.protobuf import config_pb2\n",
      "  File \"C:\\Users\\Rybak\\AppData\\Roaming\\Python\\Python37\\site-packages\\tensorflow_core\\core\\protobuf\\config_pb2.py\", line 7, in <module>\n",
      "    from google.protobuf import descriptor as _descriptor\n",
      "ModuleNotFoundError: No module named 'google.protobuf'\n",
      "Traceback (most recent call last):\n",
      "  File \"c:\\users\\rybak\\appdata\\local\\programs\\python\\python37\\lib\\site-packages\\IPython\\core\\interactiveshell.py\", line 3417, in run_code\n",
      "    exec(code_obj, self.user_global_ns, self.user_ns)\n",
      "  File \"<ipython-input-8-05c9b8348bf4>\", line 11, in <module>\n",
      "    isNSFW = nsfw_detector(\"./\" + full_path)\n",
      "NameError: name 'full_path' is not defined\n",
      "\n",
      "During handling of the above exception, another exception occurred:\n",
      "\n",
      "Traceback (most recent call last):\n",
      "  File \"c:\\users\\rybak\\appdata\\local\\programs\\python\\python37\\lib\\site-packages\\IPython\\core\\interactiveshell.py\", line 2044, in showtraceback\n",
      "    stb = value._render_traceback_()\n",
      "AttributeError: 'NameError' object has no attribute '_render_traceback_'\n",
      "\n",
      "During handling of the above exception, another exception occurred:\n",
      "\n",
      "Traceback (most recent call last):\n",
      "  File \"c:\\users\\rybak\\appdata\\local\\programs\\python\\python37\\lib\\site-packages\\IPython\\core\\interactiveshell.py\", line 3337, in run_ast_nodes\n",
      "    if (await self.run_code(code, result,  async_=asy)):\n",
      "  File \"c:\\users\\rybak\\appdata\\local\\programs\\python\\python37\\lib\\site-packages\\IPython\\core\\interactiveshell.py\", line 3434, in run_code\n",
      "    self.showtraceback(running_compiled_code=True)\n",
      "  File \"c:\\users\\rybak\\appdata\\local\\programs\\python\\python37\\lib\\site-packages\\IPython\\core\\interactiveshell.py\", line 2047, in showtraceback\n",
      "    value, tb, tb_offset=tb_offset)\n",
      "  File \"c:\\users\\rybak\\appdata\\local\\programs\\python\\python37\\lib\\site-packages\\IPython\\core\\ultratb.py\", line 1436, in structured_traceback\n",
      "    self, etype, value, tb, tb_offset, number_of_lines_of_context)\n",
      "  File \"c:\\users\\rybak\\appdata\\local\\programs\\python\\python37\\lib\\site-packages\\IPython\\core\\ultratb.py\", line 1336, in structured_traceback\n",
      "    self, etype, value, tb, tb_offset, number_of_lines_of_context\n",
      "  File \"c:\\users\\rybak\\appdata\\local\\programs\\python\\python37\\lib\\site-packages\\IPython\\core\\ultratb.py\", line 1193, in structured_traceback\n",
      "    tb_offset)\n",
      "  File \"c:\\users\\rybak\\appdata\\local\\programs\\python\\python37\\lib\\site-packages\\IPython\\core\\ultratb.py\", line 1150, in format_exception_as_a_whole\n",
      "    last_unique, recursion_repeat = find_recursion(orig_etype, evalue, records)\n",
      "  File \"c:\\users\\rybak\\appdata\\local\\programs\\python\\python37\\lib\\site-packages\\IPython\\core\\ultratb.py\", line 451, in find_recursion\n",
      "    return len(records), 0\n",
      "TypeError: object of type 'NoneType' has no len()\n",
      "\n",
      "During handling of the above exception, another exception occurred:\n",
      "\n",
      "Traceback (most recent call last):\n",
      "  File \"c:\\users\\rybak\\appdata\\local\\programs\\python\\python37\\lib\\site-packages\\IPython\\core\\interactiveshell.py\", line 2044, in showtraceback\n",
      "    stb = value._render_traceback_()\n",
      "AttributeError: 'TypeError' object has no attribute '_render_traceback_'\n",
      "\n",
      "During handling of the above exception, another exception occurred:\n",
      "\n",
      "Traceback (most recent call last):\n",
      "  File \"c:\\users\\rybak\\appdata\\local\\programs\\python\\python37\\lib\\site-packages\\IPython\\core\\ultratb.py\", line 1169, in get_records\n",
      "    return _fixed_getinnerframes(etb, number_of_lines_of_context, tb_offset)\n",
      "  File \"c:\\users\\rybak\\appdata\\local\\programs\\python\\python37\\lib\\site-packages\\IPython\\core\\ultratb.py\", line 316, in wrapped\n",
      "    return f(*args, **kwargs)\n",
      "  File \"c:\\users\\rybak\\appdata\\local\\programs\\python\\python37\\lib\\site-packages\\IPython\\core\\ultratb.py\", line 350, in _fixed_getinnerframes\n",
      "    records = fix_frame_records_filenames(inspect.getinnerframes(etb, context))\n",
      "  File \"c:\\users\\rybak\\appdata\\local\\programs\\python\\python37\\lib\\inspect.py\", line 1495, in getinnerframes\n",
      "    frameinfo = (tb.tb_frame,) + getframeinfo(tb, context)\n",
      "  File \"c:\\users\\rybak\\appdata\\local\\programs\\python\\python37\\lib\\inspect.py\", line 1453, in getframeinfo\n",
      "    filename = getsourcefile(frame) or getfile(frame)\n",
      "  File \"c:\\users\\rybak\\appdata\\local\\programs\\python\\python37\\lib\\inspect.py\", line 696, in getsourcefile\n",
      "    if getattr(getmodule(object, filename), '__loader__', None) is not None:\n",
      "  File \"c:\\users\\rybak\\appdata\\local\\programs\\python\\python37\\lib\\inspect.py\", line 733, in getmodule\n",
      "    if ismodule(module) and hasattr(module, '__file__'):\n",
      "  File \"C:\\Users\\Rybak\\AppData\\Roaming\\Python\\Python37\\site-packages\\tensorflow\\__init__.py\", line 50, in __getattr__\n",
      "    module = self._load()\n",
      "  File \"C:\\Users\\Rybak\\AppData\\Roaming\\Python\\Python37\\site-packages\\tensorflow\\__init__.py\", line 44, in _load\n",
      "    module = _importlib.import_module(self.__name__)\n",
      "  File \"c:\\users\\rybak\\appdata\\local\\programs\\python\\python37\\lib\\importlib\\__init__.py\", line 127, in import_module\n",
      "    return _bootstrap._gcd_import(name[level:], package, level)\n",
      "  File \"<frozen importlib._bootstrap>\", line 1006, in _gcd_import\n",
      "  File \"<frozen importlib._bootstrap>\", line 983, in _find_and_load\n",
      "  File \"<frozen importlib._bootstrap>\", line 953, in _find_and_load_unlocked\n",
      "  File \"<frozen importlib._bootstrap>\", line 219, in _call_with_frames_removed\n",
      "  File \"<frozen importlib._bootstrap>\", line 1006, in _gcd_import\n",
      "  File \"<frozen importlib._bootstrap>\", line 983, in _find_and_load\n",
      "  File \"<frozen importlib._bootstrap>\", line 967, in _find_and_load_unlocked\n",
      "  File \"<frozen importlib._bootstrap>\", line 677, in _load_unlocked\n",
      "  File \"<frozen importlib._bootstrap_external>\", line 728, in exec_module\n",
      "  File \"<frozen importlib._bootstrap>\", line 219, in _call_with_frames_removed\n",
      "  File \"C:\\Users\\Rybak\\AppData\\Roaming\\Python\\Python37\\site-packages\\tensorflow_core\\__init__.py\", line 42, in <module>\n",
      "    from . _api.v2 import audio\n",
      "  File \"C:\\Users\\Rybak\\AppData\\Roaming\\Python\\Python37\\site-packages\\tensorflow_core\\_api\\v2\\audio\\__init__.py\", line 10, in <module>\n",
      "    from tensorflow.python.ops.gen_audio_ops import decode_wav\n",
      "  File \"C:\\Users\\Rybak\\AppData\\Roaming\\Python\\Python37\\site-packages\\tensorflow_core\\python\\ops\\gen_audio_ops.py\", line 10, in <module>\n",
      "    from tensorflow.python.eager import context as _context\n",
      "  File \"C:\\Users\\Rybak\\AppData\\Roaming\\Python\\Python37\\site-packages\\tensorflow_core\\python\\eager\\context.py\", line 29, in <module>\n",
      "    from tensorflow.core.protobuf import config_pb2\n",
      "  File \"C:\\Users\\Rybak\\AppData\\Roaming\\Python\\Python37\\site-packages\\tensorflow_core\\core\\protobuf\\config_pb2.py\", line 7, in <module>\n",
      "    from google.protobuf import descriptor as _descriptor\n",
      "ModuleNotFoundError: No module named 'google.protobuf'\n",
      "Traceback (most recent call last):\n",
      "  File \"c:\\users\\rybak\\appdata\\local\\programs\\python\\python37\\lib\\site-packages\\IPython\\core\\interactiveshell.py\", line 3417, in run_code\n",
      "    exec(code_obj, self.user_global_ns, self.user_ns)\n",
      "  File \"<ipython-input-8-05c9b8348bf4>\", line 11, in <module>\n",
      "    isNSFW = nsfw_detector(\"./\" + full_path)\n",
      "NameError: name 'full_path' is not defined\n",
      "\n",
      "During handling of the above exception, another exception occurred:\n",
      "\n",
      "Traceback (most recent call last):\n",
      "  File \"c:\\users\\rybak\\appdata\\local\\programs\\python\\python37\\lib\\site-packages\\IPython\\core\\interactiveshell.py\", line 2044, in showtraceback\n",
      "    stb = value._render_traceback_()\n",
      "AttributeError: 'NameError' object has no attribute '_render_traceback_'\n",
      "\n",
      "During handling of the above exception, another exception occurred:\n",
      "\n",
      "Traceback (most recent call last):\n",
      "  File \"c:\\users\\rybak\\appdata\\local\\programs\\python\\python37\\lib\\site-packages\\IPython\\core\\interactiveshell.py\", line 3337, in run_ast_nodes\n",
      "    if (await self.run_code(code, result,  async_=asy)):\n",
      "  File \"c:\\users\\rybak\\appdata\\local\\programs\\python\\python37\\lib\\site-packages\\IPython\\core\\interactiveshell.py\", line 3434, in run_code\n",
      "    self.showtraceback(running_compiled_code=True)\n",
      "  File \"c:\\users\\rybak\\appdata\\local\\programs\\python\\python37\\lib\\site-packages\\IPython\\core\\interactiveshell.py\", line 2047, in showtraceback\n",
      "    value, tb, tb_offset=tb_offset)\n",
      "  File \"c:\\users\\rybak\\appdata\\local\\programs\\python\\python37\\lib\\site-packages\\IPython\\core\\ultratb.py\", line 1436, in structured_traceback\n",
      "    self, etype, value, tb, tb_offset, number_of_lines_of_context)\n",
      "  File \"c:\\users\\rybak\\appdata\\local\\programs\\python\\python37\\lib\\site-packages\\IPython\\core\\ultratb.py\", line 1336, in structured_traceback\n",
      "    self, etype, value, tb, tb_offset, number_of_lines_of_context\n",
      "  File \"c:\\users\\rybak\\appdata\\local\\programs\\python\\python37\\lib\\site-packages\\IPython\\core\\ultratb.py\", line 1193, in structured_traceback\n",
      "    tb_offset)\n",
      "  File \"c:\\users\\rybak\\appdata\\local\\programs\\python\\python37\\lib\\site-packages\\IPython\\core\\ultratb.py\", line 1150, in format_exception_as_a_whole\n",
      "    last_unique, recursion_repeat = find_recursion(orig_etype, evalue, records)\n",
      "  File \"c:\\users\\rybak\\appdata\\local\\programs\\python\\python37\\lib\\site-packages\\IPython\\core\\ultratb.py\", line 451, in find_recursion\n",
      "    return len(records), 0\n",
      "TypeError: object of type 'NoneType' has no len()\n",
      "\n",
      "During handling of the above exception, another exception occurred:\n",
      "\n",
      "Traceback (most recent call last):\n",
      "  File \"c:\\users\\rybak\\appdata\\local\\programs\\python\\python37\\lib\\site-packages\\IPython\\core\\interactiveshell.py\", line 2044, in showtraceback\n",
      "    stb = value._render_traceback_()\n",
      "AttributeError: 'TypeError' object has no attribute '_render_traceback_'\n",
      "\n",
      "During handling of the above exception, another exception occurred:\n",
      "\n",
      "Traceback (most recent call last):\n",
      "  File \"c:\\users\\rybak\\appdata\\local\\programs\\python\\python37\\lib\\site-packages\\IPython\\core\\interactiveshell.py\", line 2922, in _run_cell\n",
      "    return runner(coro)\n",
      "  File \"c:\\users\\rybak\\appdata\\local\\programs\\python\\python37\\lib\\site-packages\\IPython\\core\\async_helpers.py\", line 68, in _pseudo_sync_runner\n",
      "    coro.send(None)\n",
      "  File \"c:\\users\\rybak\\appdata\\local\\programs\\python\\python37\\lib\\site-packages\\IPython\\core\\interactiveshell.py\", line 3146, in run_cell_async\n",
      "    interactivity=interactivity, compiler=compiler, result=result)\n",
      "  File \"c:\\users\\rybak\\appdata\\local\\programs\\python\\python37\\lib\\site-packages\\IPython\\core\\interactiveshell.py\", line 3356, in run_ast_nodes\n",
      "    self.showtraceback()\n",
      "  File \"c:\\users\\rybak\\appdata\\local\\programs\\python\\python37\\lib\\site-packages\\IPython\\core\\interactiveshell.py\", line 2047, in showtraceback\n",
      "    value, tb, tb_offset=tb_offset)\n",
      "  File \"c:\\users\\rybak\\appdata\\local\\programs\\python\\python37\\lib\\site-packages\\IPython\\core\\ultratb.py\", line 1436, in structured_traceback\n",
      "    self, etype, value, tb, tb_offset, number_of_lines_of_context)\n",
      "  File \"c:\\users\\rybak\\appdata\\local\\programs\\python\\python37\\lib\\site-packages\\IPython\\core\\ultratb.py\", line 1336, in structured_traceback\n",
      "    self, etype, value, tb, tb_offset, number_of_lines_of_context\n",
      "  File \"c:\\users\\rybak\\appdata\\local\\programs\\python\\python37\\lib\\site-packages\\IPython\\core\\ultratb.py\", line 1211, in structured_traceback\n",
      "    chained_exceptions_tb_offset)\n",
      "  File \"c:\\users\\rybak\\appdata\\local\\programs\\python\\python37\\lib\\site-packages\\IPython\\core\\ultratb.py\", line 1150, in format_exception_as_a_whole\n",
      "    last_unique, recursion_repeat = find_recursion(orig_etype, evalue, records)\n",
      "  File \"c:\\users\\rybak\\appdata\\local\\programs\\python\\python37\\lib\\site-packages\\IPython\\core\\ultratb.py\", line 451, in find_recursion\n",
      "    return len(records), 0\n",
      "TypeError: object of type 'NoneType' has no len()\n",
      "\n",
      "During handling of the above exception, another exception occurred:\n",
      "\n",
      "Traceback (most recent call last):\n",
      "  File \"c:\\users\\rybak\\appdata\\local\\programs\\python\\python37\\lib\\site-packages\\IPython\\core\\interactiveshell.py\", line 2044, in showtraceback\n",
      "    stb = value._render_traceback_()\n",
      "AttributeError: 'TypeError' object has no attribute '_render_traceback_'\n",
      "\n",
      "During handling of the above exception, another exception occurred:\n",
      "\n",
      "Traceback (most recent call last):\n",
      "  File \"c:\\users\\rybak\\appdata\\local\\programs\\python\\python37\\lib\\site-packages\\IPython\\core\\ultratb.py\", line 1169, in get_records\n",
      "    return _fixed_getinnerframes(etb, number_of_lines_of_context, tb_offset)\n",
      "  File \"c:\\users\\rybak\\appdata\\local\\programs\\python\\python37\\lib\\site-packages\\IPython\\core\\ultratb.py\", line 316, in wrapped\n",
      "    return f(*args, **kwargs)\n",
      "  File \"c:\\users\\rybak\\appdata\\local\\programs\\python\\python37\\lib\\site-packages\\IPython\\core\\ultratb.py\", line 350, in _fixed_getinnerframes\n",
      "    records = fix_frame_records_filenames(inspect.getinnerframes(etb, context))\n",
      "  File \"c:\\users\\rybak\\appdata\\local\\programs\\python\\python37\\lib\\inspect.py\", line 1495, in getinnerframes\n",
      "    frameinfo = (tb.tb_frame,) + getframeinfo(tb, context)\n",
      "  File \"c:\\users\\rybak\\appdata\\local\\programs\\python\\python37\\lib\\inspect.py\", line 1453, in getframeinfo\n",
      "    filename = getsourcefile(frame) or getfile(frame)\n",
      "  File \"c:\\users\\rybak\\appdata\\local\\programs\\python\\python37\\lib\\inspect.py\", line 696, in getsourcefile\n",
      "    if getattr(getmodule(object, filename), '__loader__', None) is not None:\n",
      "  File \"c:\\users\\rybak\\appdata\\local\\programs\\python\\python37\\lib\\inspect.py\", line 733, in getmodule\n",
      "    if ismodule(module) and hasattr(module, '__file__'):\n",
      "  File \"C:\\Users\\Rybak\\AppData\\Roaming\\Python\\Python37\\site-packages\\tensorflow\\__init__.py\", line 50, in __getattr__\n",
      "    module = self._load()\n",
      "  File \"C:\\Users\\Rybak\\AppData\\Roaming\\Python\\Python37\\site-packages\\tensorflow\\__init__.py\", line 44, in _load\n",
      "    module = _importlib.import_module(self.__name__)\n",
      "  File \"c:\\users\\rybak\\appdata\\local\\programs\\python\\python37\\lib\\importlib\\__init__.py\", line 127, in import_module\n",
      "    return _bootstrap._gcd_import(name[level:], package, level)\n",
      "  File \"<frozen importlib._bootstrap>\", line 1006, in _gcd_import\n",
      "  File \"<frozen importlib._bootstrap>\", line 983, in _find_and_load\n",
      "  File \"<frozen importlib._bootstrap>\", line 953, in _find_and_load_unlocked\n",
      "  File \"<frozen importlib._bootstrap>\", line 219, in _call_with_frames_removed\n",
      "  File \"<frozen importlib._bootstrap>\", line 1006, in _gcd_import\n",
      "  File \"<frozen importlib._bootstrap>\", line 983, in _find_and_load\n",
      "  File \"<frozen importlib._bootstrap>\", line 967, in _find_and_load_unlocked\n",
      "  File \"<frozen importlib._bootstrap>\", line 677, in _load_unlocked\n",
      "  File \"<frozen importlib._bootstrap_external>\", line 728, in exec_module\n",
      "  File \"<frozen importlib._bootstrap>\", line 219, in _call_with_frames_removed\n",
      "  File \"C:\\Users\\Rybak\\AppData\\Roaming\\Python\\Python37\\site-packages\\tensorflow_core\\__init__.py\", line 42, in <module>\n",
      "    from . _api.v2 import audio\n",
      "  File \"C:\\Users\\Rybak\\AppData\\Roaming\\Python\\Python37\\site-packages\\tensorflow_core\\_api\\v2\\audio\\__init__.py\", line 10, in <module>\n",
      "    from tensorflow.python.ops.gen_audio_ops import decode_wav\n",
      "  File \"C:\\Users\\Rybak\\AppData\\Roaming\\Python\\Python37\\site-packages\\tensorflow_core\\python\\ops\\gen_audio_ops.py\", line 10, in <module>\n",
      "    from tensorflow.python.eager import context as _context\n",
      "  File \"C:\\Users\\Rybak\\AppData\\Roaming\\Python\\Python37\\site-packages\\tensorflow_core\\python\\eager\\context.py\", line 29, in <module>\n",
      "    from tensorflow.core.protobuf import config_pb2\n",
      "  File \"C:\\Users\\Rybak\\AppData\\Roaming\\Python\\Python37\\site-packages\\tensorflow_core\\core\\protobuf\\config_pb2.py\", line 7, in <module>\n",
      "    from google.protobuf import descriptor as _descriptor\n",
      "ModuleNotFoundError: No module named 'google.protobuf'\n"
     ]
    }
   ],
   "source": [
    "txt2img_url = 'http://192.168.0.109:7861/sdapi/v1/txt2img'\n",
    "print(str(len(NotSafePosPrompt)) + \" images will be generated - NSFW\")\n",
    "for row in range(len(NotSafePosPrompt)):\n",
    "    data = {'prompt': NotSafePosPrompt.at[row, 'prompt'],\n",
    "            'negative_prompt': \"(worst quality, low quality:1.4), monochrome, lowres, bad anatomy, bad hands, text, error, missing fingers, extra digit, fewer digits, cropped, worst quality, low quality, normal quality, jpeg artifacts, signature, watermark, username, blurry, deformed eyes, ((disfigured)), bad art, deformed, ((extra limbs)), ((duplicate)), morbid, multilated, bad body, on hand with less than 5 fingers, crown , stacked torses, stacked hands, totem pole\",\n",
    "            'width': 512,\n",
    "            'height': 512,\n",
    "            'steps': 50}\n",
    "    response = submit_post(txt2img_url, data)\n",
    "    fullpath = save_encoded_image(response.json()['images'][0], \"classes/new_pictures\")\n",
    "    isNSFW = nsfw_detector(\"./\" + full_path)\n",
    "    if isNSFW:\n",
    "        shutil.move(full_path, \"classes/nsfw\")\n",
    "    else:\n",
    "        shutil.move(full_path, \"classes/sfw\")\n",
    "    print(row , end='->')"
   ]
  },
  {
   "cell_type": "code",
   "execution_count": null,
   "metadata": {},
   "outputs": [],
   "source": []
  }
 ],
 "metadata": {
  "kernelspec": {
   "display_name": "Python 3",
   "language": "python",
   "name": "python3"
  },
  "language_info": {
   "codemirror_mode": {
    "name": "ipython",
    "version": 3
   },
   "file_extension": ".py",
   "mimetype": "text/x-python",
   "name": "python",
   "nbconvert_exporter": "python",
   "pygments_lexer": "ipython3",
   "version": "3.7.0"
  }
 },
 "nbformat": 4,
 "nbformat_minor": 5
}
